<!-- exception handling: To avoid sudden termination of our code
 2. it wonn't tarminate the code because of the error -->
<script>
    function add() {
        a = 20;
        b = 10;
        console.log(a+z);
    }
    try {
        console.log("task started..!");
        add();
    } catch {
        console.log("Some error occured and handled!")
    } finally {
        console.log("task ended..!");
    }
    console.log("task 1");
    console.log("task 2");

</script>